Traceback (most recent call last):
  File "/opt/homebrew/Caskroom/miniconda/base/lib/python3.8/site-packages/jupyter_cache/executors/utils.py", line 51, in single_nb_execution
    executenb(
  File "/opt/homebrew/Caskroom/miniconda/base/lib/python3.8/site-packages/nbclient/client.py", line 1204, in execute
    return NotebookClient(nb=nb, resources=resources, km=km, **kwargs).execute()
  File "/opt/homebrew/Caskroom/miniconda/base/lib/python3.8/site-packages/nbclient/util.py", line 84, in wrapped
    return just_run(coro(*args, **kwargs))
  File "/opt/homebrew/Caskroom/miniconda/base/lib/python3.8/site-packages/nbclient/util.py", line 62, in just_run
    return loop.run_until_complete(coro)
  File "/opt/homebrew/Caskroom/miniconda/base/lib/python3.8/asyncio/base_events.py", line 616, in run_until_complete
    return future.result()
  File "/opt/homebrew/Caskroom/miniconda/base/lib/python3.8/site-packages/nbclient/client.py", line 663, in async_execute
    await self.async_execute_cell(
  File "/opt/homebrew/Caskroom/miniconda/base/lib/python3.8/site-packages/nbclient/client.py", line 965, in async_execute_cell
    await self._check_raise_for_error(cell, cell_index, exec_reply)
  File "/opt/homebrew/Caskroom/miniconda/base/lib/python3.8/site-packages/nbclient/client.py", line 862, in _check_raise_for_error
    raise CellExecutionError.from_cell_and_msg(cell, exec_reply_content)
nbclient.exceptions.CellExecutionError: An error occurred while executing the following cell:
------------------
!pip install yfinance

import os
import sys
from google.colab import drive
import warnings
warnings.filterwarnings('ignore')
import pandas as pd
import numpy as np
import shutil
import yfinance as yf
yf.pdr_override()

root_dir = '/content/drive/' 
drive.mount(root_dir)

main_dir = root_dir+'MyDrive/teaching/ddmif_spring_2023/' 
data_dir = main_dir+'data/'
ddmif_dir = root_dir+'MyDrive/teaching/ddmif'
sys.path.append(main_dir)
sys.path.append(data_dir)
os.chdir(main_dir)

ddmif_dir = root_dir+'MyDrive/teaching/ddmif_spring_2023/ddmif'
try:
  shutil.rmtree(ddmif_dir)
except:
  pass

!git clone https://github.com/naftalic/ddmif.git
import ddmif.ddmif_functions as ddmif
#pip freeze > requirements.txt
------------------

[0;31m---------------------------------------------------------------------------[0m
[0;31mModuleNotFoundError[0m                       Traceback (most recent call last)
Input [0;32mIn [7][0m, in [0;36m<cell line: 5>[0;34m()[0m
[1;32m      3[0m [38;5;28;01mimport[39;00m [38;5;21;01mos[39;00m
[1;32m      4[0m [38;5;28;01mimport[39;00m [38;5;21;01msys[39;00m
[0;32m----> 5[0m [38;5;28;01mfrom[39;00m [38;5;21;01mgoogle[39;00m[38;5;21;01m.[39;00m[38;5;21;01mcolab[39;00m [38;5;28;01mimport[39;00m drive
[1;32m      6[0m [38;5;28;01mimport[39;00m [38;5;21;01mwarnings[39;00m
[1;32m      7[0m warnings[38;5;241m.[39mfilterwarnings([38;5;124m'[39m[38;5;124mignore[39m[38;5;124m'[39m)

[0;31mModuleNotFoundError[0m: No module named 'google'
ModuleNotFoundError: No module named 'google'

